2023-04-12 11:33:08,141 INFO    MainThread:17292 [internal.py:wandb_internal():86] W&B internal server running at pid: 17292, started at: 2023-04-12 11:33:08.135535
2023-04-12 11:33:08,143 INFO    WriterThread:17292 [datastore.py:open_for_write():77] open: D:\documents\SelfFiles\zjut\VIM\code\FGVC-PIM\wandb\run-20230412_113307-24v3lhkj\run-24v3lhkj.wandb
2023-04-12 11:33:08,144 DEBUG   HandlerThread:17292 [handler.py:handle_request():126] handle_request: check_version
2023-04-12 11:33:08,145 DEBUG   SenderThread:17292 [sender.py:send():185] send: header
2023-04-12 11:33:08,145 DEBUG   SenderThread:17292 [sender.py:send_request():199] send_request: check_version
2023-04-12 11:33:08,962 DEBUG   SenderThread:17292 [sender.py:send():185] send: run
2023-04-12 11:33:09,744 ERROR   SenderThread:17292 [internal_api.py:execute():135] 403 response executing GraphQL.
2023-04-12 11:33:09,744 ERROR   SenderThread:17292 [internal_api.py:execute():136] {"errors":[{"message":"permission denied","path":["upsertBucket"],"extensions":{"code":"PERMISSION_ERROR"}}],"data":{"upsertBucket":null}}
2023-04-12 11:33:09,972 INFO    HandlerThread:17292 [handler.py:finish():683] shutting down handler
2023-04-12 11:33:09,973 INFO    WriterThread:17292 [datastore.py:close():281] close: D:\documents\SelfFiles\zjut\VIM\code\FGVC-PIM\wandb\run-20230412_113307-24v3lhkj\run-24v3lhkj.wandb
2023-04-12 11:33:10,159 ERROR   MainThread:17292 [internal.py:wandb_internal():157] Thread SenderThread:
Traceback (most recent call last):
  File "D:\environment\Anaconda3\envs\fgvc\lib\site-packages\wandb\sdk\lib\retry.py", line 102, in __call__
    result = self._call_fn(*args, **kwargs)
  File "D:\environment\Anaconda3\envs\fgvc\lib\site-packages\wandb\sdk\internal\internal_api.py", line 138, in execute
    six.reraise(*sys.exc_info())
  File "D:\environment\Anaconda3\envs\fgvc\lib\site-packages\six.py", line 719, in reraise
    raise value
  File "D:\environment\Anaconda3\envs\fgvc\lib\site-packages\wandb\sdk\internal\internal_api.py", line 132, in execute
    return self.client.execute(*args, **kwargs)
  File "D:\environment\Anaconda3\envs\fgvc\lib\site-packages\wandb\vendor\gql-0.2.0\gql\client.py", line 52, in execute
    result = self._get_result(document, *args, **kwargs)
  File "D:\environment\Anaconda3\envs\fgvc\lib\site-packages\wandb\vendor\gql-0.2.0\gql\client.py", line 60, in _get_result
    return self.transport.execute(document, *args, **kwargs)
  File "D:\environment\Anaconda3\envs\fgvc\lib\site-packages\wandb\vendor\gql-0.2.0\gql\transport\requests.py", line 39, in execute
    request.raise_for_status()
  File "D:\environment\Anaconda3\envs\fgvc\lib\site-packages\requests\models.py", line 1021, in raise_for_status
    raise HTTPError(http_error_msg, response=self)
requests.exceptions.HTTPError: 403 Client Error: Forbidden for url: https://api.wandb.ai/graphql

During handling of the above exception, another exception occurred:

Traceback (most recent call last):
  File "D:\environment\Anaconda3\envs\fgvc\lib\site-packages\wandb\apis\normalize.py", line 24, in wrapper
    return func(*args, **kwargs)
  File "D:\environment\Anaconda3\envs\fgvc\lib\site-packages\wandb\sdk\internal\internal_api.py", line 1133, in upsert_run
    response = self.gql(mutation, variable_values=variable_values, **kwargs)
  File "D:\environment\Anaconda3\envs\fgvc\lib\site-packages\wandb\sdk\lib\retry.py", line 118, in __call__
    if not check_retry_fn(e):
  File "D:\environment\Anaconda3\envs\fgvc\lib\site-packages\wandb\util.py", line 815, in no_retry_auth
    raise CommError("Permission denied, ask the project owner to grant you access")
wandb.errors.CommError: Permission denied, ask the project owner to grant you access

During handling of the above exception, another exception occurred:

Traceback (most recent call last):
  File "D:\environment\Anaconda3\envs\fgvc\lib\site-packages\wandb\sdk\internal\internal_util.py", line 52, in run
    self._run()
  File "D:\environment\Anaconda3\envs\fgvc\lib\site-packages\wandb\sdk\internal\internal_util.py", line 102, in _run
    self._process(record)
  File "D:\environment\Anaconda3\envs\fgvc\lib\site-packages\wandb\sdk\internal\internal.py", line 290, in _process
    self._sm.send(record)
  File "D:\environment\Anaconda3\envs\fgvc\lib\site-packages\wandb\sdk\internal\sender.py", line 187, in send
    send_handler(record)
  File "D:\environment\Anaconda3\envs\fgvc\lib\site-packages\wandb\sdk\internal\sender.py", line 629, in send_run
    self._init_run(run, config_value_dict)
  File "D:\environment\Anaconda3\envs\fgvc\lib\site-packages\wandb\sdk\internal\sender.py", line 651, in _init_run
    server_run, inserted = self._api.upsert_run(
  File "D:\environment\Anaconda3\envs\fgvc\lib\site-packages\wandb\apis\normalize.py", line 62, in wrapper
    six.reraise(CommError, CommError(message, err), sys.exc_info()[2])
  File "D:\environment\Anaconda3\envs\fgvc\lib\site-packages\six.py", line 718, in reraise
    raise value.with_traceback(tb)
  File "D:\environment\Anaconda3\envs\fgvc\lib\site-packages\wandb\apis\normalize.py", line 24, in wrapper
    return func(*args, **kwargs)
  File "D:\environment\Anaconda3\envs\fgvc\lib\site-packages\wandb\sdk\internal\internal_api.py", line 1133, in upsert_run
    response = self.gql(mutation, variable_values=variable_values, **kwargs)
  File "D:\environment\Anaconda3\envs\fgvc\lib\site-packages\wandb\sdk\lib\retry.py", line 118, in __call__
    if not check_retry_fn(e):
  File "D:\environment\Anaconda3\envs\fgvc\lib\site-packages\wandb\util.py", line 815, in no_retry_auth
    raise CommError("Permission denied, ask the project owner to grant you access")
wandb.errors.CommError: Permission denied, ask the project owner to grant you access
2023-04-12 11:33:12,189 INFO    MainThread:17292 [internal.py:handle_exit():76] Internal process exited
